Workbook
Name Slicer_Diabetes_Status: #N/A
Name Slicer_Weight_Status: #N/A

Sheet Customer Names
A1: Customer ID | B1: name
A2: Id1 | B2: Hawks, Ms. Kelly
A3: Id2 | B3: Lehner, Mr. Matthew D
A4: Id3 | B4: Lu, Mr. Phil
A5: Id4 | B5: Osborne, Ms. Kelsey
A6: Id5 | B6: Kadala, Ms. Kristyn
A7: Id6 | B7: Baker, Mr. Russell B.
A8: Id7 | B8: Macpherson, Mr. Scott
A9: Id8 | B9: Hallman, Mr. Stephen
A10: Id9 | B10: Moran, Mr. Patrick R.
A11: Id10 | B11: Benner, Ms. Brooke N.
A12: Id11 | B12: Fierro Vargas, Ms. Paola Andrea
... A2336: Id2335 | B2336: German, Mr. Aaron K

Sheet Medical Examinations
A1: Customer ID | B1: BMI | C1: HBA1C | D1: Heart Issues | E1: Any Transplants | F1: Cancer history | G1: NumberOfMajorSurgeries | H1: smoker
A2: Id1 | B2: 47.41 | C2: 7.47 | D2: No | E2: No | F2: No | G2: No major surgery | H2: yes
A3: Id2 | B3: 30.36 | C3: 5.77 | D3: No | E3: No | F3: No | G3: No major surgery | H3: yes
A4: Id3 | B4: 34.485 | C4: 11.87 | D4: yes | E4: No | F4: No | G4: 2 | H4: yes
A5: Id4 | B5: 38.095 | C5: 6.05 | D5: No | E5: No | F5: No | G5: No major surgery | H5: yes
A6: Id5 | B6: 35.53 | C6: 5.45 | D6: No | E6: No | F6: No | G6: No major surgery | H6: yes
A7: Id6 | B7: 32.8 | C7: 6.59 | D7: No | E7: No | F7: No | G7: No major surgery | H7: yes
A8: Id7 | B8: 36.4 | C8: 6.07 | D8: No | E8: No | F8: No | G8: No major surgery | H8: yes
A9: Id8 | B9: 36.96 | C9: 7.93 | D9: No | E9: No | F9: No | G9: 3 | H9: yes
A10: Id9 | B10: 41.14 | C10: 9.58 | D10: yes | E10: No | F10: Yes | G10: 1 | H10: yes
A11: Id10 | B11: 38.06 | C11: 10.79 | D11: No | E11: No | F11: No | G11: No major surgery | H11: yes
A12: Id11 | B12: 37.7 | C12: 5.96 | D12: yes | E12: No | F12: No | G12: 2 | H12: yes
A13: Id12 | B13: 42.13 | C13: 11.9 | D13: No | E13: No | F13: No | G13: No major surgery | H13: yes
A14: Id13 | B14: 40.92 | C14: 8.41 | D14: No | E14: No | F14: No | G14: No major surgery | H14: yes
A15: Id14 | B15: 40.565 | C15: 7.02 | D15: No | E15: No | F15: No | G15: No major surgery | H15: yes
A16: Id15 | B16: 36.385 | C16: 7.59 | D16: yes | E16: No | F16: No | G16: 2 | H16: yes
A17: Id16 | B17: 39.9 | C17: 11.32 | D17: No | E17: No | F17: No | G17: No major surgery | H17: yes
A18: Id17 | B18: 33.8 | C18: 7.67 | D18: No | E18: No | F18: No | G18: 3 | H18: yes
A19: Id18 | B19: 36.765 | C19: 7.29 | D19: yes | E19: No | F19: Yes | G19: 1 | H19: yes
A20: Id19 | B20: 36.955 | C20: 4.72 | D20: yes | E20: No | F20: No | G20: 1 | H20: yes
A21: Id20 | B21: 42.9 | C21: 11.41 | D21: No | E21: No | F21: No | G21: No major surgery | H21: yes
A22: Id21 | B22: 36.3 | C22: 11.5 | D22: yes | E22: No | F22: No | G22: 2 | H22: yes
A23: Id22 | B23: 32.2 | C23: 6.22 | D23: yes | E23: No | F23: No | G23: 2 | H23: yes
A24: Id23 | B24: 31.3 | C24: 11.38 | D24: No | E24: No | F24: No | G24: 3 | H24: yes
A25: Id24 | B25: 41.8 | C25: 7.89 | D25: yes | E25: No | F25: No | G25: 2 | H25: yes
A26: Id25 | B26: 35.09 | C26: 4.38 | D26: yes | E26: No | F26: No | G26: 2 | H26: yes
A27: Id26 | B27: 33.88 | C27: 7.01 | D27: No | E27: No | F27: No | G27: 3 | H27: yes
A28: Id27 | B28: 30.875 | C28: 11.88 | D28: No | E28: No | F28: No | G28: No major surgery | H28: yes
A29: Id28 | B29: 36.86 | C29: 5.19 | D29: yes | E29: No | F29: Yes | G29: 1 | H29: yes
A30: Id29 | B30: 35.86 | C30: 6.74 | D30: yes | E30: No | F30: No | G30: 2 | H30: yes
A31: Id30 | B31: 37.05 | C31: 8.44 | D31: No | E31: No | F31: No | G31: No major surgery | H31: yes
A32: Id31 | B32: 43.89 | C32: 8.71 | D32: No | E32: No | F32: No | G32: No major surgery | H32: yes
A33: Id32 | B33: 42.35 | C33: 5.08 | D33: yes | E33: No | F33: No | G33: No major surgery | H33: yes
A34: Id33 | B34: 31.35 | C34: 6.86 | D34: No | E34: No | F34: No | G34: No major surgery | H34: yes
A35: Id34 | B35: 47.6 | C35: 5.95 | D35: yes | E35: No | F35: No | G35: No major surgery | H35: yes
A36: Id35 | B36: 46.2 | C36: 6.09 | D36: No | E36: No | F36: Yes | G36: 1 | H36: yes
A37: Id36 | B37: 32.015 | C37: 11.75 | D37: No | E37: No | F37: No | G37: No major surgery | H37: yes
A38: Id37 | B38: 40.565 | C38: 7.37 | D38: No | E38: No | F38: No | G38: No major surgery | H38: yes
A39: Id38 | B39: 32.45 | C39: 11.91 | D39: No | E39: No | F39: No | G39: No major surgery | H39: yes
A40: Id39 | B40: 34.96 | C40: 6.52 | D40: No | E40: No | F40: No | G40: No major surgery | H40: yes
...

Sheet Hospitalisation Details
A1: Customer ID | B1: year | C1: month | D1: date | E1: children | F1: charges | G1: Hospital tier | H1: City tier | I1: State ID
A2: Id2335 | B2: 1992 | C2: Jul | D2: 9 | E2: 0 | F2: 563.84 | G2: tier - 2 | H2: tier - 3 | I2: R1013
A3: Id2334 | B3: 1992 | C3: Nov | D3: 30 | E3: 0 | F3: 570.62 | G3: tier - 2 | H3: tier - 1 | I3: R1013
A4: Id2333 | B4: 1993 | C4: Jun | D4: 30 | E4: 0 | F4: 600 | G4: tier - 2 | H4: tier - 1 | I4: R1013
A5: Id2332 | B5: 1992 | C5: Sep | D5: 13 | E5: 0 | F5: 604.54 | G5: tier - 3 | H5: tier - 3 | I5: R1013
A6: Id2331 | B6: 1998 | C6: Jul | D6: 27 | E6: 0 | F6: 637.26 | G6: tier - 3 | H6: tier - 3 | I6: R1013
A7: Id2330 | B7: 2001 | C7: Nov | D7: 20 | E7: 0 | F7: 646.14 | G7: tier - 3 | H7: tier - 3 | I7: R1012
A8: Id2329 | B8: 1993 | C8: Jun | D8: 1 | E8: 0 | F8: 650 | G8: tier - 3 | H8: tier - 3 | I8: R1013
A9: Id2328 | B9: 1995 | C9: Jul | D9: 4 | E9: 0 | F9: 650 | G9: tier - 3 | H9: tier - 3 | I9: R1013
A10: Id2327 | B10: 2002 | C10: Nov | D10: 29 | E10: 0 | F10: 668 | G10: tier - 3 | H10: tier - 2 | I10: R1012
A11: Id2326 | B11: 1997 | C11: Nov | D11: 9 | E11: 0 | F11: 670 | G11: tier - 3 | H11: tier - 3 | I11: R1013
A12: Id2325 | B12: 2001 | C12: Sep | D12: 12 | E12: 0 | F12: 687.54 | G12: tier - 3 | H12: tier - 2 | I12: R1013
A13: Id2324 | B13: 1999 | C13: Dec | D13: 26 | E13: 0 | F13: 700 | G13: ? | H13: tier - 3 | I13: R1013
... A1050: Id1290 | B1050: 1977 | C1050: Jul | D1050: 26 | E1050: 2 | F1050: 8527.53 | G1050: tier - 2 | H1050: tier - 2 | I1050: R1013
A1051: Id1289 | B1051: ? | C1051: Jul | D1051: 24 | E1051: 0 | F1051: 8534.67 | G1051: tier - 2 | H1051: tier - 3 | I1051: R1024
A1052: Id1288 | B1052: 1981 | C1052: Dec | D1052: 27 | E1052: 3 | F1052: 8538.29 | G1052: tier - 2 | H1052: tier - 3 | I1052: R1024
A1053: Id1287 | B1053: 1975 | C1053: Nov | D1053: 6 | E1053: 1 | F1053: 8539.67 | G1053: tier - 2 | H1053: tier - 3 | I1053: R1011
A1054: Id1286 | B1054: ? | C1054: Dec | D1054: 12 | E1054: 1 | F1054: 8547.69 | G1054: tier - 2 | H1054: tier - 1 | I1054: R1013
A1055: Id1285 | B1055: 1975 | C1055: Aug | D1055: 6 | E1055: 1 | F1055: 8551.35 | G1055: tier - 2 | H1055: tier - 2 | I1055: R1011
A1056: Id1284 | B1056: 1975 | C1056: Aug | D1056: 21 | E1056: 1 | F1056: 8556.91 | G1056: tier - 2 | H1056: tier - 1 | I1056: R1011
A1057: Id1283 | B1057: 1988 | C1057: Sep | D1057: 21 | E1057: 3 | F1057: 8567.25 | G1057: tier - 2 | H1057: tier - 1 | I1057: R1012
A1058: Id1282 | B1058: 1975 | C1058: Sep | D1058: 26 | E1058: 1 | F1058: 8569.86 | G1058: tier - 2 | H1058: tier - 3 | I1058: R1013
A1059: Id1281 | B1059: 1982 | C1059: Dec | D1059: 6 | E1059: 3 | F1059: 8572.04 | G1059: tier - 2 | H1059: tier - 2 | I1059: R1021
A1060: Id1280 | B1060: 1987 | C1060: Nov | D1060: 11 | E1060: 3 | F1060: 8573.3 | G1060: tier - 2 | H1060: tier - 2 | I1060: R1021
A1061: Id1279 | B1061: 1983 | C1061: Dec | D1061: 30 | E1061: 5 | F1061: 8582.3 | G1061: tier - 2 | H1061: tier - 1 | I1061: R1013
A1062: Id1278 | B1062: 1983 | C1062: Jul | D1062: 25 | E1062: 5 | F1062: 8596.83 | G1062: tier - 2 | H1062: tier - 3 | I1062: R1013
A1063: Id1277 | B1063: 1973 | C1063: Jul | D1063: 11 | E1063: 0 | F1063: 8601.33 | G1063: tier - 2 | H1063: tier - 1 | I1063: R1013
A1064: Id1276 | B1064: 1977 | C1064: Sep | D1064: 24 | E1064: 2 | F1064: 8603.82 | G1064: tier - 2 | H1064: tier - 1 | I1064: R1019
A1065: Id1275 | B1065: 1977 | C1065: Nov | D1065: 12 | E1065: 2 | F1065: 8604.48 | G1065: tier - 3 | H1065: tier - 2 | I1065: R1016
A1066: Id1274 | B1066: 1977 | C1066: Oct | D1066: 15 | E1066: 3 | F1066: 8605.36 | G1066: tier - 2 | H1066: tier - 2 | I1066: R1013
... A2344: Id1 | B2344: 1968 | C2344: Oct | D2344: 12 | E2344: 0 | F2344: 63770.43 | G2344: tier - 1 | H2344: tier - 3 | I2344: R1013

Sheet Customer Names_A_sheet
A1: Customer ID | B1: name | C1: Title | D1: First Name | E1: Last Name
A2: Id1 | B2: Hawks, Ms. Kelly | C2: Ms. | D2: Kelly | E2: Hawks
A3: Id2 | B3: Lehner, Mr. Matthew D | C3: Mr. | D3: Matthew D | E3: Lehner
A4: Id3 | B4: Lu, Mr. Phil | C4: Mr. | D4: Phil | E4: Lu
A5: Id4 | B5: Osborne, Ms. Kelsey | C5: Ms. | D5: Kelsey | E5: Osborne
A6: Id5 | B6: Kadala, Ms. Kristyn | C6: Ms. | D6: Kristyn | E6: Kadala
A7: Id6 | B7: Baker, Mr. Russell B. | C7: Mr. | D7: Russell B. | E7: Baker
A8: Id7 | B8: Macpherson, Mr. Scott | C8: Mr. | D8: Scott | E8: Macpherson
A9: Id8 | B9: Hallman, Mr. Stephen | C9: Mr. | D9: Stephen | E9: Hallman
A10: Id9 | B10: Moran, Mr. Patrick R. | C10: Mr. | D10: Patrick R. | E10: Moran
A11: Id10 | B11: Benner, Ms. Brooke N. | C11: Ms. | D11: Brooke N. | E11: Benner
A12: Id11 | B12: Fierro Vargas, Ms. Paola Andrea | C12: Ms. | D12: Ms. Paola Andrea | E12: Fierro Vargas
... A2336: Id2335 | B2336: German, Mr. Aaron K | C2336: Mr. | D2336: Aaron K | E2336: German

Sheet Medical Examinations_A_sheet
A1: Customer ID | B1: BMI | C1: HBA1C | D1: Heart Issues | E1: Any Transplants | F1: Cancer history | G1: NumberOfMajorSurgeries | H1: Smoker | I1: Weight Status | J1: Diabetes Status | N1: Count of missing value with '?' | O1: =COUNTIF('Medical Examinations'!A2:H2336,"~?") -> 2
A2: Id1 | B2: 47.41 | C2: 7.47 | D2: =CLEAN(TRIM(PROPER('Medical Examinations'!D2))) -> No | E2: No | F2: No | G2: 0 | H2: =SUBSTITUTE(CLEAN(TRIM(PROPER('Medical Examinations'!H2))),"?","No") -> Yes | I2: =IF('Medical Examinations_A_sheet'!B2<18.5, "Underweight", IF('Medical Examinations_A_sheet'!B2<25, "Normal Weight", IF('Medical Examinations_A_sheet'!B2<30, "Overweight", "Obesity"))) -> Obesity | J2: =IF('Medical Examinations_A_sheet'!C2<5.7,"Normal",IF('Medical Examinations_A_sheet'!C2<6.5,"Prediabetes","Diabetes")) -> Diabetes | N2: most frequently occurring values in the ‘smoker’, | O2: {=INDEX('Medical Examinations'!H2:H2336,_xlfn.MODE.MULT(MATCH('Medical Examinations'!H2:H2336,'Medical Examinations'!H2:H2336,0)))} -> No
A3: Id2 | B3: 30.36 | C3: 5.77 | D3: =CLEAN(TRIM(PROPER('Medical Examinations'!D3))) -> No | E3: No | F3: No | G3: 0 | H3: =SUBSTITUTE(CLEAN(TRIM(PROPER('Medical Examinations'!H3))),"?","No") -> Yes | I3: =IF('Medical Examinations_A_sheet'!B3<18.5, "Underweight", IF('Medical Examinations_A_sheet'!B3<25, "Normal Weight", IF('Medical Examinations_A_sheet'!B3<30, "Overweight", "Obesity"))) -> Obesity | J3: =IF('Medical Examinations_A_sheet'!C3<5.7,"Normal",IF('Medical Examinations_A_sheet'!C3<6.5,"Prediabetes","Diabetes")) -> Prediabetes
A4: Id3 | B4: 34.485 | C4: 11.87 | D4: =CLEAN(TRIM(PROPER('Medical Examinations'!D4))) -> Yes | E4: No | F4: No | G4: 2 | H4: =SUBSTITUTE(CLEAN(TRIM(PROPER('Medical Examinations'!H4))),"?","No") -> Yes | I4: =IF('Medical Examinations_A_sheet'!B4<18.5, "Underweight", IF('Medical Examinations_A_sheet'!B4<25, "Normal Weight", IF('Medical Examinations_A_sheet'!B4<30, "Overweight", "Obesity"))) -> Obesity | J4: =IF('Medical Examinations_A_sheet'!C4<5.7,"Normal",IF('Medical Examinations_A_sheet'!C4<6.5,"Prediabetes","Diabetes")) -> Diabetes
A5: Id4 | B5: 38.095 | C5: 6.05 | D5: =CLEAN(TRIM(PROPER('Medical Examinations'!D5))) -> No | E5: No | F5: No | G5: 0 | H5: =SUBSTITUTE(CLEAN(TRIM(PROPER('Medical Examinations'!H5))),"?","No") -> Yes | I5: =IF('Medical Examinations_A_sheet'!B5<18.5, "Underweight", IF('Medical Examinations_A_sheet'!B5<25, "Normal Weight", IF('Medical Examinations_A_sheet'!B5<30, "Overweight", "Obesity"))) -> Obesity | J5: =IF('Medical Examinations_A_sheet'!C5<5.7,"Normal",IF('Medical Examinations_A_sheet'!C5<6.5,"Prediabetes","Diabetes")) -> Prediabetes
A6: Id5 | B6: 35.53 | C6: 5.45 | D6: =CLEAN(TRIM(PROPER('Medical Examinations'!D6))) -> No | E6: No | F6: No | G6: 0 | H6: =SUBSTITUTE(CLEAN(TRIM(PROPER('Medical Examinations'!H6))),"?","No") -> Yes | I6: =IF('Medical Examinations_A_sheet'!B6<18.5, "Underweight", IF('Medical Examinations_A_sheet'!B6<25, "Normal Weight", IF('Medical Examinations_A_sheet'!B6<30, "Overweight", "Obesity"))) -> Obesity | J6: =IF('Medical Examinations_A_sheet'!C6<5.7,"Normal",IF('Medical Examinations_A_sheet'!C6<6.5,"Prediabetes","Diabetes")) -> Normal
A7: Id6 | B7: 32.8 | C7: 6.59 | D7: =CLEAN(TRIM(PROPER('Medical Examinations'!D7))) -> No | E7: No | F7: No | G7: 0 | H7: =SUBSTITUTE(CLEAN(TRIM(PROPER('Medical Examinations'!H7))),"?","No") -> Yes | I7: =IF('Medical Examinations_A_sheet'!B7<18.5, "Underweight", IF('Medical Examinations_A_sheet'!B7<25, "Normal Weight", IF('Medical Examinations_A_sheet'!B7<30, "Overweight", "Obesity"))) -> Obesity | J7: =IF('Medical Examinations_A_sheet'!C7<5.7,"Normal",IF('Medical Examinations_A_sheet'!C7<6.5,"Prediabetes","Diabetes")) -> Diabetes
A8: Id7 | B8: 36.4 | C8: 6.07 | D8: =CLEAN(TRIM(PROPER('Medical Examinations'!D8))) -> No | E8: No | F8: No | G8: 0 | H8: =SUBSTITUTE(CLEAN(TRIM(PROPER('Medical Examinations'!H8))),"?","No") -> Yes | I8: =IF('Medical Examinations_A_sheet'!B8<18.5, "Underweight", IF('Medical Examinations_A_sheet'!B8<25, "Normal Weight", IF('Medical Examinations_A_sheet'!B8<30, "Overweight", "Obesity"))) -> Obesity | J8: =IF('Medical Examinations_A_sheet'!C8<5.7,"Normal",IF('Medical Examinations_A_sheet'!C8<6.5,"Prediabetes","Diabetes")) -> Prediabetes
A9: Id8 | B9: 36.96 | C9: 7.93 | D9: =CLEAN(TRIM(PROPER('Medical Examinations'!D9))) -> No | E9: No | F9: No | G9: 3 | H9: =SUBSTITUTE(CLEAN(TRIM(PROPER('Medical Examinations'!H9))),"?","No") -> Yes | I9: =IF('Medical Examinations_A_sheet'!B9<18.5, "Underweight", IF('Medical Examinations_A_sheet'!B9<25, "Normal Weight", IF('Medical Examinations_A_sheet'!B9<30, "Overweight", "Obesity"))) -> Obesity | J9: =IF('Medical Examinations_A_sheet'!C9<5.7,"Normal",IF('Medical Examinations_A_sheet'!C9<6.5,"Prediabetes","Diabetes")) -> Diabetes
A10: Id9 | B10: 41.14 | C10: 9.58 | D10: =CLEAN(TRIM(PROPER('Medical Examinations'!D10))) -> Yes | E10: No | F10: Yes | G10: 1 | H10: =SUBSTITUTE(CLEAN(TRIM(PROPER('Medical Examinations'!H10))),"?","No") -> Yes | I10: =IF('Medical Examinations_A_sheet'!B10<18.5, "Underweight", IF('Medical Examinations_A_sheet'!B10<25, "Normal Weight", IF('Medical Examinations_A_sheet'!B10<30, "Overweight", "Obesity"))) -> Obesity | J10: =IF('Medical Examinations_A_sheet'!C10<5.7,"Normal",IF('Medical Examinations_A_sheet'!C10<6.5,"Prediabetes","Diabetes")) -> Diabetes
A11: Id10 | B11: 38.06 | C11: 10.79 | D11: =CLEAN(TRIM(PROPER('Medical Examinations'!D11))) -> No | E11: No | F11: No | G11: 0 | H11: =SUBSTITUTE(CLEAN(TRIM(PROPER('Medical Examinations'!H11))),"?","No") -> Yes | I11: =IF('Medical Examinations_A_sheet'!B11<18.5, "Underweight", IF('Medical Examinations_A_sheet'!B11<25, "Normal Weight", IF('Medical Examinations_A_sheet'!B11<30, "Overweight", "Obesity"))) -> Obesity | J11: =IF('Medical Examinations_A_sheet'!C11<5.7,"Normal",IF('Medical Examinations_A_sheet'!C11<6.5,"Prediabetes","Diabetes")) -> Diabetes
A12: Id11 | B12: 37.7 | C12: 5.96 | D12: =CLEAN(TRIM(PROPER('Medical Examinations'!D12))) -> Yes | E12: No | F12: No | G12: 2 | H12: =SUBSTITUTE(CLEAN(TRIM(PROPER('Medical Examinations'!H12))),"?","No") -> Yes | I12: =IF('Medical Examinations_A_sheet'!B12<18.5, "Underweight", IF('Medical Examinations_A_sheet'!B12<25, "Normal Weight", IF('Medical Examinations_A_sheet'!B12<30, "Overweight", "Obesity"))) -> Obesity | J12: =IF('Medical Examinations_A_sheet'!C12<5.7,"Normal",IF('Medical Examinations_A_sheet'!C12<6.5,"Prediabetes","Diabetes")) -> Prediabetes
A13: Id12 | B13: 42.13 | C13: 11.9 | D13: =CLEAN(TRIM(PROPER('Medical Examinations'!D13))) -> No | E13: No | F13: No | G13: 0 | H13: =SUBSTITUTE(CLEAN(TRIM(PROPER('Medical Examinations'!H13))),"?","No") -> Yes | I13: =IF('Medical Examinations_A_sheet'!B13<18.5, "Underweight", IF('Medical Examinations_A_sheet'!B13<25, "Normal Weight", IF('Medical Examinations_A_sheet'!B13<30, "Overweight", "Obesity"))) -> Obesity | J13: =IF('Medical Examinations_A_sheet'!C13<5.7,"Normal",IF('Medical Examinations_A_sheet'!C13<6.5,"Prediabetes","Diabetes")) -> Diabetes
A14: Id13 | B14: 40.92 | C14: 8.41 | D14: =CLEAN(TRIM(PROPER('Medical Examinations'!D14))) -> No | E14: No | F14: No | G14: 0 | H14: =SUBSTITUTE(CLEAN(TRIM(PROPER('Medical Examinations'!H14))),"?","No") -> Yes | I14: =IF('Medical Examinations_A_sheet'!B14<18.5, "Underweight", IF('Medical Examinations_A_sheet'!B14<25, "Normal Weight", IF('Medical Examinations_A_sheet'!B14<30, "Overweight", "Obesity"))) -> Obesity | J14: =IF('Medical Examinations_A_sheet'!C14<5.7,"Normal",IF('Medical Examinations_A_sheet'!C14<6.5,"Prediabetes","Diabetes")) -> Diabetes
... A2336: Id2335 | B2336: 17.58 | C2336: 4.51 | D2336: =CLEAN(TRIM(PROPER('Medical Examinations'!D2336))) -> No | E2336: No | F2336: No | G2336: 1 | H2336: =SUBSTITUTE(CLEAN(TRIM(PROPER('Medical Examinations'!H2336))),"?","No") -> No | I2336: =IF('Medical Examinations_A_sheet'!B2336<18.5, "Underweight", IF('Medical Examinations_A_sheet'!B2336<25, "Normal Weight", IF('Medical Examinations_A_sheet'!B2336<30, "Overweight", "Obesity"))) -> Underweight | J2336: =IF('Medical Examinations_A_sheet'!C2336<5.7,"Normal",IF('Medical Examinations_A_sheet'!C2336<6.5,"Prediabetes","Diabetes")) -> Normal

Sheet Hospitalisation Details_A_sheet
A1: Customer ID | B1: year | C1: month | D1: date | E1: children | F1: charges | G1: Hospital tier | H1: City tier | I1: State ID | J1: Date of Birth | K1: Age | O1: Count of missing value with '?' | P1: =COUNTIF('Hospitalisation Details'!A2:I2344,"~?") -> 15
A2: Id2335 | B2: 1992 | C2: Jul | D2: 9 | E2: 0 | F2: 563.84 | G2: tier - 2 | H2: tier - 3 | I2: R1013 | J2: =_xlfn.TEXTJOIN("-",TRUE,D2,C2,B2) -> 9-Jul-1992 | K2: =DATEDIF(J2, DATE(2023,6,8), "Y") -> 30 | O2: Average year rounded to the nearest integer | P2: =ROUND(AVERAGE('Hospitalisation Details'!B2:B2344),0) -> 1983
A3: Id2334 | B3: 1992 | C3: Nov | D3: 30 | E3: 0 | F3: 570.62 | G3: tier - 2 | H3: tier - 1 | I3: R1013 | J3: =_xlfn.TEXTJOIN("-",TRUE,D3,C3,B3) -> 30-Nov-1992 | K3: =DATEDIF(J3, DATE(2023,6,8), "Y") -> 30 | O3: most frequently occurring values in 'Hospital tier' | P3: {=INDEX('Hospitalisation Details'!G2:G2344,_xlfn.MODE.MULT(MATCH('Hospitalisation Details'!G2:G2344,'Hospitalisation Details'!G2:G2344,0)))} -> tier - 2
A4: Id2333 | B4: 1993 | C4: Jun | D4: 30 | E4: 0 | F4: 600 | G4: tier - 2 | H4: tier - 1 | I4: R1013 | J4: =_xlfn.TEXTJOIN("-",TRUE,D4,C4,B4) -> 30-Jun-1993 | K4: =DATEDIF(J4, DATE(2023,6,8), "Y") -> 29 | O4: most frequently occurring values in 'City tier' | P4: {=INDEX('Hospitalisation Details'!H2:H2344,_xlfn.MODE.MULT(MATCH('Hospitalisation Details'!H2:H2344,'Hospitalisation Details'!H2:H2344,0)))} -> tier - 2
A5: Id2332 | B5: 1992 | C5: Sep | D5: 13 | E5: 0 | F5: 604.54 | G5: tier - 3 | H5: tier - 3 | I5: R1013 | J5: =_xlfn.TEXTJOIN("-",TRUE,D5,C5,B5) -> 13-Sep-1992 | K5: =DATEDIF(J5, DATE(2023,6,8), "Y") -> 30
A6: Id2331 | B6: 1998 | C6: Jul | D6: 27 | E6: 0 | F6: 637.26 | G6: tier - 3 | H6: tier - 3 | I6: R1013 | J6: =_xlfn.TEXTJOIN("-",TRUE,D6,C6,B6) -> 27-Jul-1998 | K6: =DATEDIF(J6, DATE(2023,6,8), "Y") -> 24
A7: Id2330 | B7: 2001 | C7: Nov | D7: 20 | E7: 0 | F7: 646.14 | G7: tier - 3 | H7: tier - 3 | I7: R1012 | J7: =_xlfn.TEXTJOIN("-",TRUE,D7,C7,B7) -> 20-Nov-2001 | K7: =DATEDIF(J7, DATE(2023,6,8), "Y") -> 21
A8: Id2329 | B8: 1993 | C8: Jun | D8: 1 | E8: 0 | F8: 650 | G8: tier - 3 | H8: tier - 3 | I8: R1013 | J8: =_xlfn.TEXTJOIN("-",TRUE,D8,C8,B8) -> 1-Jun-1993 | K8: =DATEDIF(J8, DATE(2023,6,8), "Y") -> 30
A9: Id2328 | B9: 1995 | C9: Jul | D9: 4 | E9: 0 | F9: 650 | G9: tier - 3 | H9: tier - 3 | I9: R1013 | J9: =_xlfn.TEXTJOIN("-",TRUE,D9,C9,B9) -> 4-Jul-1995 | K9: =DATEDIF(J9, DATE(2023,6,8), "Y") -> 27
A10: Id2327 | B10: 2002 | C10: Nov | D10: 29 | E10: 0 | F10: 668 | G10: tier - 3 | H10: tier - 2 | I10: R1012 | J10: =_xlfn.TEXTJOIN("-",TRUE,D10,C10,B10) -> 29-Nov-2002 | K10: =DATEDIF(J10, DATE(2023,6,8), "Y") -> 20
A11: Id2326 | B11: 1997 | C11: Nov | D11: 9 | E11: 0 | F11: 670 | G11: tier - 3 | H11: tier - 3 | I11: R1013 | J11: =_xlfn.TEXTJOIN("-",TRUE,D11,C11,B11) -> 9-Nov-1997 | K11: =DATEDIF(J11, DATE(2023,6,8), "Y") -> 25
A12: Id2325 | B12: 2001 | C12: Sep | D12: 12 | E12: 0 | F12: 687.54 | G12: tier - 3 | H12: tier - 2 | I12: R1013 | J12: =_xlfn.TEXTJOIN("-",TRUE,D12,C12,B12) -> 12-Sep-2001 | K12: =DATEDIF(J12, DATE(2023,6,8), "Y") -> 21
A13: Id2324 | B13: 1999 | C13: Dec | D13: 26 | E13: 0 | F13: 700 | G13: tier - 2 | H13: tier - 3 | I13: R1013 | J13: =_xlfn.TEXTJOIN("-",TRUE,D13,C13,B13) -> 26-Dec-1999 | K13: =DATEDIF(J13, DATE(2023,6,8), "Y") -> 23
A14: Id2323 | B14: 1999 | C14: Dec | D14: 14 | E14: 0 | F14: 722.99 | G14: tier - 3 | H14: tier - 1 | I14: R1013 | J14: =_xlfn.TEXTJOIN("-",TRUE,D14,C14,B14) -> 14-Dec-1999 | K14: =DATEDIF(J14, DATE(2023,6,8), "Y") -> 23
A15: Id2322 | B15: 2002 | C15: Sep | D15: 19 | E15: 0 | F15: 750 | G15: tier - 3 | H15: tier - 1 | I15: R1012 | J15: =_xlfn.TEXTJOIN("-",TRUE,D15,C15,B15) -> 19-Sep-2002 | K15: =DATEDIF(J15, DATE(2023,6,8), "Y") -> 20
A16: Id2321 | B16: 1993 | C16: Aug | D16: 9 | E16: 0 | F16: 760 | G16: tier - 3 | H16: tier - 1 | I16: R1013 | J16: =_xlfn.TEXTJOIN("-",TRUE,D16,C16,B16) -> 9-Aug-1993 | K16: =DATEDIF(J16, DATE(2023,6,8), "Y") -> 29
... A2344: Id1 | B2344: 1968 | C2344: Oct | D2344: 12 | E2344: 0 | F2344: 63770.43 | G2344: tier - 1 | H2344: tier - 3 | I2344: R1013 | J2344: =_xlfn.TEXTJOIN("-",TRUE,D2344,C2344,B2344) -> 12-Oct-1968 | K2344: =DATEDIF(J2344, DATE(2023,6,8), "Y") -> 54

Sheet Healthcare
A1: Customer ID | B1: First Name | C1: BMI | D1: HBA1C | E1: Heart Issues | F1: Any Transplants | G1: Cancer history | H1: NumberOfMajorSurgeries | I1: smoker | J1: Weight Status | K1: Diabetes Status | L1: charges | M1: Hospital tier | N1: City tier | O1: State ID | P1: Date of Birth | Q1: Age
A2: Id1 | B2: =VLOOKUP('Customer Names_A_sheet'!$A2,'Customer Names_A_sheet'!$A$1:$E$2336,4,FALSE) -> Kelly | C2: =VLOOKUP($A2, 'Medical Examinations_A_sheet'!$A$1:$J$2336, COLUMN('Medical Examinations_A_sheet'!B2), FALSE) -> 47.41 | D2: =VLOOKUP($A2, 'Medical Examinations_A_sheet'!$A$1:$J$2336, COLUMN('Medical Examinations_A_sheet'!C2), FALSE) -> 7.47 | E2: =VLOOKUP($A2, 'Medical Examinations_A_sheet'!$A$1:$J$2336, COLUMN('Medical Examinations_A_sheet'!D2), FALSE) -> No | F2: =VLOOKUP($A2, 'Medical Examinations_A_sheet'!$A$1:$J$2336, COLUMN('Medical Examinations_A_sheet'!E2), FALSE) -> No | G2: =VLOOKUP($A2, 'Medical Examinations_A_sheet'!$A$1:$J$2336, COLUMN('Medical Examinations_A_sheet'!F2), FALSE) -> No | H2: =VLOOKUP($A2, 'Medical Examinations_A_sheet'!$A$1:$J$2336, COLUMN('Medical Examinations_A_sheet'!G2), FALSE) -> 0 | I2: =VLOOKUP($A2, 'Medical Examinations_A_sheet'!$A$1:$J$2336, COLUMN('Medical Examinations_A_sheet'!H2), FALSE) -> Yes | J2: =VLOOKUP($A2, 'Medical Examinations_A_sheet'!$A$1:$J$2336, COLUMN('Medical Examinations_A_sheet'!I2), FALSE) -> Obesity | K2: =VLOOKUP($A2, 'Medical Examinations_A_sheet'!$A$1:$J$2336, COLUMN('Medical Examinations_A_sheet'!J2), FALSE) -> Diabetes | L2: =VLOOKUP(Healthcare!$A2,'Hospitalisation Details_A_sheet'!$A$1:$K$2344,COLUMN('Hospitalisation Details_A_sheet'!F1),FALSE) -> 63770.43 | M2: =VLOOKUP(Healthcare!$A2,'Hospitalisation Details_A_sheet'!$A$1:$K$2344,COLUMN('Hospitalisation Details_A_sheet'!G1),FALSE) -> tier - 1 | N2: =VLOOKUP(Healthcare!$A2,'Hospitalisation Details_A_sheet'!$A$1:$K$2344,COLUMN('Hospitalisation Details_A_sheet'!H1),FALSE) -> tier - 3 | O2: =VLOOKUP(Healthcare!$A2,'Hospitalisation Details_A_sheet'!$A$1:$K$2344,COLUMN('Hospitalisation Details_A_sheet'!I1),FALSE) -> R1013 | P2: =VLOOKUP(Healthcare!$A2,'Hospitalisation Details_A_sheet'!$A$1:$K$2344,COLUMN('Hospitalisation Details_A_sheet'!J1),FALSE) -> 12-Oct-1968 | Q2: =VLOOKUP(Healthcare!$A2,'Hospitalisation Details_A_sheet'!$A$1:$K$2344,COLUMN('Hospitalisation Details_A_sheet'!K1),FALSE) -> 54
A3: Id2 | B3: =VLOOKUP('Customer Names_A_sheet'!$A3,'Customer Names_A_sheet'!$A$1:$E$2336,4,FALSE) -> Matthew D | C3: =VLOOKUP($A3, 'Medical Examinations_A_sheet'!$A$1:$J$2336, COLUMN('Medical Examinations_A_sheet'!B3), FALSE) -> 30.36 | D3: =VLOOKUP($A3, 'Medical Examinations_A_sheet'!$A$1:$J$2336, COLUMN('Medical Examinations_A_sheet'!C3), FALSE) -> 5.77 | E3: =VLOOKUP($A3, 'Medical Examinations_A_sheet'!$A$1:$J$2336, COLUMN('Medical Examinations_A_sheet'!D3), FALSE) -> No | F3: =VLOOKUP($A3, 'Medical Examinations_A_sheet'!$A$1:$J$2336, COLUMN('Medical Examinations_A_sheet'!E3), FALSE) -> No | G3: =VLOOKUP($A3, 'Medical Examinations_A_sheet'!$A$1:$J$2336, COLUMN('Medical Examinations_A_sheet'!F3), FALSE) -> No | H3: =VLOOKUP($A3, 'Medical Examinations_A_sheet'!$A$1:$J$2336, COLUMN('Medical Examinations_A_sheet'!G3), FALSE) -> 0 | I3: =VLOOKUP($A3, 'Medical Examinations_A_sheet'!$A$1:$J$2336, COLUMN('Medical Examinations_A_sheet'!H3), FALSE) -> Yes | J3: =VLOOKUP($A3, 'Medical Examinations_A_sheet'!$A$1:$J$2336, COLUMN('Medical Examinations_A_sheet'!I3), FALSE) -> Obesity | K3: =VLOOKUP($A3, 'Medical Examinations_A_sheet'!$A$1:$J$2336, COLUMN('Medical Examinations_A_sheet'!J3), FALSE) -> Prediabetes | L3: =VLOOKUP(Healthcare!$A3,'Hospitalisation Details_A_sheet'!$A$1:$K$2344,COLUMN('Hospitalisation Details_A_sheet'!F2),FALSE) -> 62592.87 | M3: =VLOOKUP(Healthcare!$A3,'Hospitalisation Details_A_sheet'!$A$1:$K$2344,COLUMN('Hospitalisation Details_A_sheet'!G2),FALSE) -> tier - 2 | N3: =VLOOKUP(Healthcare!$A3,'Hospitalisation Details_A_sheet'!$A$1:$K$2344,COLUMN('Hospitalisation Details_A_sheet'!H2),FALSE) -> tier - 3 | O3: =VLOOKUP(Healthcare!$A3,'Hospitalisation Details_A_sheet'!$A$1:$K$2344,COLUMN('Hospitalisation Details_A_sheet'!I2),FALSE) -> R1013 | P3: =VLOOKUP(Healthcare!$A3,'Hospitalisation Details_A_sheet'!$A$1:$K$2344,COLUMN('Hospitalisation Details_A_sheet'!J2),FALSE) -> 8-Jun-1977 | Q3: =VLOOKUP(Healthcare!$A3,'Hospitalisation Details_A_sheet'!$A$1:$K$2344,COLUMN('Hospitalisation Details_A_sheet'!K2),FALSE) -> 46
A4: Id3 | B4: =VLOOKUP('Customer Names_A_sheet'!$A4,'Customer Names_A_sheet'!$A$1:$E$2336,4,FALSE) -> Phil | C4: =VLOOKUP($A4, 'Medical Examinations_A_sheet'!$A$1:$J$2336, COLUMN('Medical Examinations_A_sheet'!B4), FALSE) -> 34.485 | D4: =VLOOKUP($A4, 'Medical Examinations_A_sheet'!$A$1:$J$2336, COLUMN('Medical Examinations_A_sheet'!C4), FALSE) -> 11.87 | E4: =VLOOKUP($A4, 'Medical Examinations_A_sheet'!$A$1:$J$2336, COLUMN('Medical Examinations_A_sheet'!D4), FALSE) -> Yes | F4: =VLOOKUP($A4, 'Medical Examinations_A_sheet'!$A$1:$J$2336, COLUMN('Medical Examinations_A_sheet'!E4), FALSE) -> No | G4: =VLOOKUP($A4, 'Medical Examinations_A_sheet'!$A$1:$J$2336, COLUMN('Medical Examinations_A_sheet'!F4), FALSE) -> No | H4: =VLOOKUP($A4, 'Medical Examinations_A_sheet'!$A$1:$J$2336, COLUMN('Medical Examinations_A_sheet'!G4), FALSE) -> 2 | I4: =VLOOKUP($A4, 'Medical Examinations_A_sheet'!$A$1:$J$2336, COLUMN('Medical Examinations_A_sheet'!H4), FALSE) -> Yes | J4: =VLOOKUP($A4, 'Medical Examinations_A_sheet'!$A$1:$J$2336, COLUMN('Medical Examinations_A_sheet'!I4), FALSE) -> Obesity | K4: =VLOOKUP($A4, 'Medical Examinations_A_sheet'!$A$1:$J$2336, COLUMN('Medical Examinations_A_sheet'!J4), FALSE) -> Diabetes | L4: =VLOOKUP(Healthcare!$A4,'Hospitalisation Details_A_sheet'!$A$1:$K$2344,COLUMN('Hospitalisation Details_A_sheet'!F3),FALSE) -> 60021.4 | M4: =VLOOKUP(Healthcare!$A4,'Hospitalisation Details_A_sheet'!$A$1:$K$2344,COLUMN('Hospitalisation Details_A_sheet'!G3),FALSE) -> tier - 1 | N4: =VLOOKUP(Healthcare!$A4,'Hospitalisation Details_A_sheet'!$A$1:$K$2344,COLUMN('Hospitalisation Details_A_sheet'!H3),FALSE) -> tier - 1 | O4: =VLOOKUP(Healthcare!$A4,'Hospitalisation Details_A_sheet'!$A$1:$K$2344,COLUMN('Hospitalisation Details_A_sheet'!I3),FALSE) -> R1012 | P4: =VLOOKUP(Healthcare!$A4,'Hospitalisation Details_A_sheet'!$A$1:$K$2344,COLUMN('Hospitalisation Details_A_sheet'!J3),FALSE) -> 11-Sep-1970 | Q4: =VLOOKUP(Healthcare!$A4,'Hospitalisation Details_A_sheet'!$A$1:$K$2344,COLUMN('Hospitalisation Details_A_sheet'!K3),FALSE) -> 52
A5: Id4 | B5: =VLOOKUP('Customer Names_A_sheet'!$A5,'Customer Names_A_sheet'!$A$1:$E$2336,4,FALSE) -> Kelsey | C5: =VLOOKUP($A5, 'Medical Examinations_A_sheet'!$A$1:$J$2336, COLUMN('Medical Examinations_A_sheet'!B5), FALSE) -> 38.095 | D5: =VLOOKUP($A5, 'Medical Examinations_A_sheet'!$A$1:$J$2336, COLUMN('Medical Examinations_A_sheet'!C5), FALSE) -> 6.05 | E5: =VLOOKUP($A5, 'Medical Examinations_A_sheet'!$A$1:$J$2336, COLUMN('Medical Examinations_A_sheet'!D5), FALSE) -> No | F5: =VLOOKUP($A5, 'Medical Examinations_A_sheet'!$A$1:$J$2336, COLUMN('Medical Examinations_A_sheet'!E5), FALSE) -> No | G5: =VLOOKUP($A5, 'Medical Examinations_A_sheet'!$A$1:$J$2336, COLUMN('Medical Examinations_A_sheet'!F5), FALSE) -> No | H5: =VLOOKUP($A5, 'Medical Examinations_A_sheet'!$A$1:$J$2336, COLUMN('Medical Examinations_A_sheet'!G5), FALSE) -> 0 | I5: =VLOOKUP($A5, 'Medical Examinations_A_sheet'!$A$1:$J$2336, COLUMN('Medical Examinations_A_sheet'!H5), FALSE) -> Yes | J5: =VLOOKUP($A5, 'Medical Examinations_A_sheet'!$A$1:$J$2336, COLUMN('Medical Examinations_A_sheet'!I5), FALSE) -> Obesity | K5: =VLOOKUP($A5, 'Medical Examinations_A_sheet'!$A$1:$J$2336, COLUMN('Medical Examinations_A_sheet'!J5), FALSE) -> Prediabetes | L5: =VLOOKUP(Healthcare!$A5,'Hospitalisation Details_A_sheet'!$A$1:$K$2344,COLUMN('Hospitalisation Details_A_sheet'!F4),FALSE) -> 58571.07 | M5: =VLOOKUP(Healthcare!$A5,'Hospitalisation Details_A_sheet'!$A$1:$K$2344,COLUMN('Hospitalisation Details_A_sheet'!G4),FALSE) -> tier - 1 | N5: =VLOOKUP(Healthcare!$A5,'Hospitalisation Details_A_sheet'!$A$1:$K$2344,COLUMN('Hospitalisation Details_A_sheet'!H4),FALSE) -> tier - 3 | O5: =VLOOKUP(Healthcare!$A5,'Hospitalisation Details_A_sheet'!$A$1:$K$2344,COLUMN('Hospitalisation Details_A_sheet'!I4),FALSE) -> R1024 | P5: =VLOOKUP(Healthcare!$A5,'Hospitalisation Details_A_sheet'!$A$1:$K$2344,COLUMN('Hospitalisation Details_A_sheet'!J4),FALSE) -> 6-Jun-1991 | Q5: =VLOOKUP(Healthcare!$A5,'Hospitalisation Details_A_sheet'!$A$1:$K$2344,COLUMN('Hospitalisation Details_A_sheet'!K4),FALSE) -> 32
A6: Id5 | B6: =VLOOKUP('Customer Names_A_sheet'!$A6,'Customer Names_A_sheet'!$A$1:$E$2336,4,FALSE) -> Kristyn | C6: =VLOOKUP($A6, 'Medical Examinations_A_sheet'!$A$1:$J$2336, COLUMN('Medical Examinations_A_sheet'!B6), FALSE) -> 35.53 | D6: =VLOOKUP($A6, 'Medical Examinations_A_sheet'!$A$1:$J$2336, COLUMN('Medical Examinations_A_sheet'!C6), FALSE) -> 5.45 | E6: =VLOOKUP($A6, 'Medical Examinations_A_sheet'!$A$1:$J$2336, COLUMN('Medical Examinations_A_sheet'!D6), FALSE) -> No | F6: =VLOOKUP($A6, 'Medical Examinations_A_sheet'!$A$1:$J$2336, COLUMN('Medical Examinations_A_sheet'!E6), FALSE) -> No | G6: =VLOOKUP($A6, 'Medical Examinations_A_sheet'!$A$1:$J$2336, COLUMN('Medical Examinations_A_sheet'!F6), FALSE) -> No | H6: =VLOOKUP($A6, 'Medical Examinations_A_sheet'!$A$1:$J$2336, COLUMN('Medical Examinations_A_sheet'!G6), FALSE) -> 0 | I6: =VLOOKUP($A6, 'Medical Examinations_A_sheet'!$A$1:$J$2336, COLUMN('Medical Examinations_A_sheet'!H6), FALSE) -> Yes | J6: =VLOOKUP($A6, 'Medical Examinations_A_sheet'!$A$1:$J$2336, COLUMN('Medical Examinations_A_sheet'!I6), FALSE) -> Obesity | K6: =VLOOKUP($A6, 'Medical Examinations_A_sheet'!$A$1:$J$2336, COLUMN('Medical Examinations_A_sheet'!J6), FALSE) -> Normal | L6: =VLOOKUP(Healthcare!$A6,'Hospitalisation Details_A_sheet'!$A$1:$K$2344,COLUMN('Hospitalisation Details_A_sheet'!F5),FALSE) -> 55135.4 | M6: =VLOOKUP(Healthcare!$A6,'Hospitalisation Details_A_sheet'!$A$1:$K$2344,COLUMN('Hospitalisation Details_A_sheet'!G5),FALSE) -> tier - 1 | N6: =VLOOKUP(Healthcare!$A6,'Hospitalisation Details_A_sheet'!$A$1:$K$2344,COLUMN('Hospitalisation Details_A_sheet'!H5),FALSE) -> tier - 2 | O6: =VLOOKUP(Healthcare!$A6,'Hospitalisation Details_A_sheet'!$A$1:$K$2344,COLUMN('Hospitalisation Details_A_sheet'!I5),FALSE) -> R1012 | P6: =VLOOKUP(Healthcare!$A6,'Hospitalisation Details_A_sheet'!$A$1:$K$2344,COLUMN('Hospitalisation Details_A_sheet'!J5),FALSE) -> 19-Jun-1989 | Q6: =VLOOKUP(Healthcare!$A6,'Hospitalisation Details_A_sheet'!$A$1:$K$2344,COLUMN('Hospitalisation Details_A_sheet'!K5),FALSE) -> 33
A7: Id6 | B7: =VLOOKUP('Customer Names_A_sheet'!$A7,'Customer Names_A_sheet'!$A$1:$E$2336,4,FALSE) -> Russell B. | C7: =VLOOKUP($A7, 'Medical Examinations_A_sheet'!$A$1:$J$2336, COLUMN('Medical Examinations_A_sheet'!B7), FALSE) -> 32.8 | D7: =VLOOKUP($A7, 'Medical Examinations_A_sheet'!$A$1:$J$2336, COLUMN('Medical Examinations_A_sheet'!C7), FALSE) -> 6.59 | E7: =VLOOKUP($A7, 'Medical Examinations_A_sheet'!$A$1:$J$2336, COLUMN('Medical Examinations_A_sheet'!D7), FALSE) -> No | F7: =VLOOKUP($A7, 'Medical Examinations_A_sheet'!$A$1:$J$2336, COLUMN('Medical Examinations_A_sheet'!E7), FALSE) -> No | G7: =VLOOKUP($A7, 'Medical Examinations_A_sheet'!$A$1:$J$2336, COLUMN('Medical Examinations_A_sheet'!F7), FALSE) -> No | H7: =VLOOKUP($A7, 'Medical Examinations_A_sheet'!$A$1:$J$2336, COLUMN('Medical Examinations_A_sheet'!G7), FALSE) -> 0 | I7: =VLOOKUP($A7, 'Medical Examinations_A_sheet'!$A$1:$J$2336, COLUMN('Medical Examinations_A_sheet'!H7), FALSE) -> Yes | J7: =VLOOKUP($A7, 'Medical Examinations_A_sheet'!$A$1:$J$2336, COLUMN('Medical Examinations_A_sheet'!I7), FALSE) -> Obesity | K7: =VLOOKUP($A7, 'Medical Examinations_A_sheet'!$A$1:$J$2336, COLUMN('Medical Examinations_A_sheet'!J7), FALSE) -> Diabetes | L7: =VLOOKUP(Healthcare!$A7,'Hospitalisation Details_A_sheet'!$A$1:$K$2344,COLUMN('Hospitalisation Details_A_sheet'!F6),FALSE) -> 52590.83 | M7: =VLOOKUP(Healthcare!$A7,'Hospitalisation Details_A_sheet'!$A$1:$K$2344,COLUMN('Hospitalisation Details_A_sheet'!G6),FALSE) -> tier - 1 | N7: =VLOOKUP(Healthcare!$A7,'Hospitalisation Details_A_sheet'!$A$1:$K$2344,COLUMN('Hospitalisation Details_A_sheet'!H6),FALSE) -> tier - 3 | O7: =VLOOKUP(Healthcare!$A7,'Hospitalisation Details_A_sheet'!$A$1:$K$2344,COLUMN('Hospitalisation Details_A_sheet'!I6),FALSE) -> R1011 | P7: =VLOOKUP(Healthcare!$A7,'Hospitalisation Details_A_sheet'!$A$1:$K$2344,COLUMN('Hospitalisation Details_A_sheet'!J6),FALSE) -> 4-Aug-1962 | Q7: =VLOOKUP(Healthcare!$A7,'Hospitalisation Details_A_sheet'!$A$1:$K$2344,COLUMN('Hospitalisation Details_A_sheet'!K6),FALSE) -> 60
A8: Id7 | B8: =VLOOKUP('Customer Names_A_sheet'!$A8,'Customer Names_A_sheet'!$A$1:$E$2336,4,FALSE) -> Scott | C8: =VLOOKUP($A8, 'Medical Examinations_A_sheet'!$A$1:$J$2336, COLUMN('Medical Examinations_A_sheet'!B8), FALSE) -> 36.4 | D8: =VLOOKUP($A8, 'Medical Examinations_A_sheet'!$A$1:$J$2336, COLUMN('Medical Examinations_A_sheet'!C8), FALSE) -> 6.07 | E8: =VLOOKUP($A8, 'Medical Examinations_A_sheet'!$A$1:$J$2336, COLUMN('Medical Examinations_A_sheet'!D8), FALSE) -> No | F8: =VLOOKUP($A8, 'Medical Examinations_A_sheet'!$A$1:$J$2336, COLUMN('Medical Examinations_A_sheet'!E8), FALSE) -> No | G8: =VLOOKUP($A8, 'Medical Examinations_A_sheet'!$A$1:$J$2336, COLUMN('Medical Examinations_A_sheet'!F8), FALSE) -> No | H8: =VLOOKUP($A8, 'Medical Examinations_A_sheet'!$A$1:$J$2336, COLUMN('Medical Examinations_A_sheet'!G8), FALSE) -> 0 | I8: =VLOOKUP($A8, 'Medical Examinations_A_sheet'!$A$1:$J$2336, COLUMN('Medical Examinations_A_sheet'!H8), FALSE) -> Yes | J8: =VLOOKUP($A8, 'Medical Examinations_A_sheet'!$A$1:$J$2336, COLUMN('Medical Examinations_A_sheet'!I8), FALSE) -> Obesity | K8: =VLOOKUP($A8, 'Medical Examinations_A_sheet'!$A$1:$J$2336, COLUMN('Medical Examinations_A_sheet'!J8), FALSE) -> Prediabetes | L8: =VLOOKUP(Healthcare!$A8,'Hospitalisation Details_A_sheet'!$A$1:$K$2344,COLUMN('Hospitalisation Details_A_sheet'!F7),FALSE) -> 51194.56 | M8: =VLOOKUP(Healthcare!$A8,'Hospitalisation Details_A_sheet'!$A$1:$K$2344,COLUMN('Hospitalisation Details_A_sheet'!G7),FALSE) -> tier - 1 | N8: =VLOOKUP(Healthcare!$A8,'Hospitalisation Details_A_sheet'!$A$1:$K$2344,COLUMN('Hospitalisation Details_A_sheet'!H7),FALSE) -> tier - 3 | O8: =VLOOKUP(Healthcare!$A8,'Hospitalisation Details_A_sheet'!$A$1:$K$2344,COLUMN('Hospitalisation Details_A_sheet'!I7),FALSE) -> R1011 | P8: =VLOOKUP(Healthcare!$A8,'Hospitalisation Details_A_sheet'!$A$1:$K$2344,COLUMN('Hospitalisation Details_A_sheet'!J7),FALSE) -> 27-Oct-1994 | Q8: =VLOOKUP(Healthcare!$A8,'Hospitalisation Details_A_sheet'!$A$1:$K$2344,COLUMN('Hospitalisation Details_A_sheet'!K7),FALSE) -> 28
A9: Id8 | B9: =VLOOKUP('Customer Names_A_sheet'!$A9,'Customer Names_A_sheet'!$A$1:$E$2336,4,FALSE) -> Stephen | C9: =VLOOKUP($A9, 'Medical Examinations_A_sheet'!$A$1:$J$2336, COLUMN('Medical Examinations_A_sheet'!B9), FALSE) -> 36.96 | D9: =VLOOKUP($A9, 'Medical Examinations_A_sheet'!$A$1:$J$2336, COLUMN('Medical Examinations_A_sheet'!C9), FALSE) -> 7.93 | E9: =VLOOKUP($A9, 'Medical Examinations_A_sheet'!$A$1:$J$2336, COLUMN('Medical Examinations_A_sheet'!D9), FALSE) -> No | F9: =VLOOKUP($A9, 'Medical Examinations_A_sheet'!$A$1:$J$2336, COLUMN('Medical Examinations_A_sheet'!E9), FALSE) -> No | G9: =VLOOKUP($A9, 'Medical Examinations_A_sheet'!$A$1:$J$2336, COLUMN('Medical Examinations_A_sheet'!F9), FALSE) -> No | H9: =VLOOKUP($A9, 'Medical Examinations_A_sheet'!$A$1:$J$2336, COLUMN('Medical Examinations_A_sheet'!G9), FALSE) -> 3 | I9: =VLOOKUP($A9, 'Medical Examinations_A_sheet'!$A$1:$J$2336, COLUMN('Medical Examinations_A_sheet'!H9), FALSE) -> Yes | J9: =VLOOKUP($A9, 'Medical Examinations_A_sheet'!$A$1:$J$2336, COLUMN('Medical Examinations_A_sheet'!I9), FALSE) -> Obesity | K9: =VLOOKUP($A9, 'Medical Examinations_A_sheet'!$A$1:$J$2336, COLUMN('Medical Examinations_A_sheet'!J9), FALSE) -> Diabetes | L9: =VLOOKUP(Healthcare!$A9,'Hospitalisation Details_A_sheet'!$A$1:$K$2344,COLUMN('Hospitalisation Details_A_sheet'!F8),FALSE) -> 49577.66 | M9: =VLOOKUP(Healthcare!$A9,'Hospitalisation Details_A_sheet'!$A$1:$K$2344,COLUMN('Hospitalisation Details_A_sheet'!G8),FALSE) -> tier - 2 | N9: =VLOOKUP(Healthcare!$A9,'Hospitalisation Details_A_sheet'!$A$1:$K$2344,COLUMN('Hospitalisation Details_A_sheet'!H8),FALSE) -> tier - 2 | O9: =VLOOKUP(Healthcare!$A9,'Hospitalisation Details_A_sheet'!$A$1:$K$2344,COLUMN('Hospitalisation Details_A_sheet'!I8),FALSE) -> R1013 | P9: =VLOOKUP(Healthcare!$A9,'Hospitalisation Details_A_sheet'!$A$1:$K$2344,COLUMN('Hospitalisation Details_A_sheet'!J8),FALSE) -> 27-Jun-1958 | Q9: =VLOOKUP(Healthcare!$A9,'Hospitalisation Details_A_sheet'!$A$1:$K$2344,COLUMN('Hospitalisation Details_A_sheet'!K8),FALSE) -> 64
A10: Id9 | B10: =VLOOKUP('Customer Names_A_sheet'!$A10,'Customer Names_A_sheet'!$A$1:$E$2336,4,FALSE) -> Patrick R. | C10: =VLOOKUP($A10, 'Medical Examinations_A_sheet'!$A$1:$J$2336, COLUMN('Medical Examinations_A_sheet'!B10), FALSE) -> 41.14 | D10: =VLOOKUP($A10, 'Medical Examinations_A_sheet'!$A$1:$J$2336, COLUMN('Medical Examinations_A_sheet'!C10), FALSE) -> 9.58 | E10: =VLOOKUP($A10, 'Medical Examinations_A_sheet'!$A$1:$J$2336, COLUMN('Medical Examinations_A_sheet'!D10), FALSE) -> Yes | F10: =VLOOKUP($A10, 'Medical Examinations_A_sheet'!$A$1:$J$2336, COLUMN('Medical Examinations_A_sheet'!E10), FALSE) -> No | G10: =VLOOKUP($A10, 'Medical Examinations_A_sheet'!$A$1:$J$2336, COLUMN('Medical Examinations_A_sheet'!F10), FALSE) -> Yes | H10: =VLOOKUP($A10, 'Medical Examinations_A_sheet'!$A$1:$J$2336, COLUMN('Medical Examinations_A_sheet'!G10), FALSE) -> 1 | I10: =VLOOKUP($A10, 'Medical Examinations_A_sheet'!$A$1:$J$2336, COLUMN('Medical Examinations_A_sheet'!H10), FALSE) -> Yes | J10: =VLOOKUP($A10, 'Medical Examinations_A_sheet'!$A$1:$J$2336, COLUMN('Medical Examinations_A_sheet'!I10), FALSE) -> Obesity | K10: =VLOOKUP($A10, 'Medical Examinations_A_sheet'!$A$1:$J$2336, COLUMN('Medical Examinations_A_sheet'!J10), FALSE) -> Diabetes | L10: =VLOOKUP(Healthcare!$A10,'Hospitalisation Details_A_sheet'!$A$1:$K$2344,COLUMN('Hospitalisation Details_A_sheet'!F9),FALSE) -> 48970.25 | M10: =VLOOKUP(Healthcare!$A10,'Hospitalisation Details_A_sheet'!$A$1:$K$2344,COLUMN('Hospitalisation Details_A_sheet'!G9),FALSE) -> tier - 1 | N10: =VLOOKUP(Healthcare!$A10,'Hospitalisation Details_A_sheet'!$A$1:$K$2344,COLUMN('Hospitalisation Details_A_sheet'!H9),FALSE) -> tier - 2 | O10: =VLOOKUP(Healthcare!$A10,'Hospitalisation Details_A_sheet'!$A$1:$K$2344,COLUMN('Hospitalisation Details_A_sheet'!I9),FALSE) -> R1013 | P10: =VLOOKUP(Healthcare!$A10,'Hospitalisation Details_A_sheet'!$A$1:$K$2344,COLUMN('Hospitalisation Details_A_sheet'!J9),FALSE) -> 4-Sep-1963 | Q10: =VLOOKUP(Healthcare!$A10,'Hospitalisation Details_A_sheet'!$A$1:$K$2344,COLUMN('Hospitalisation Details_A_sheet'!K9),FALSE) -> 59
A11: Id10 | B11: =VLOOKUP('Customer Names_A_sheet'!$A11,'Customer Names_A_sheet'!$A$1:$E$2336,4,FALSE) -> Brooke N. | C11: =VLOOKUP($A11, 'Medical Examinations_A_sheet'!$A$1:$J$2336, COLUMN('Medical Examinations_A_sheet'!B11), FALSE) -> 38.06 | D11: =VLOOKUP($A11, 'Medical Examinations_A_sheet'!$A$1:$J$2336, COLUMN('Medical Examinations_A_sheet'!C11), FALSE) -> 10.79 | E11: =VLOOKUP($A11, 'Medical Examinations_A_sheet'!$A$1:$J$2336, COLUMN('Medical Examinations_A_sheet'!D11), FALSE) -> No | F11: =VLOOKUP($A11, 'Medical Examinations_A_sheet'!$A$1:$J$2336, COLUMN('Medical Examinations_A_sheet'!E11), FALSE) -> No | G11: =VLOOKUP($A11, 'Medical Examinations_A_sheet'!$A$1:$J$2336, COLUMN('Medical Examinations_A_sheet'!F11), FALSE) -> No | H11: =VLOOKUP($A11, 'Medical Examinations_A_sheet'!$A$1:$J$2336, COLUMN('Medical Examinations_A_sheet'!G11), FALSE) -> 0 | I11: =VLOOKUP($A11, 'Medical Examinations_A_sheet'!$A$1:$J$2336, COLUMN('Medical Examinations_A_sheet'!H11), FALSE) -> Yes | J11: =VLOOKUP($A11, 'Medical Examinations_A_sheet'!$A$1:$J$2336, COLUMN('Medical Examinations_A_sheet'!I11), FALSE) -> Obesity | K11: =VLOOKUP($A11, 'Medical Examinations_A_sheet'!$A$1:$J$2336, COLUMN('Medical Examinations_A_sheet'!J11), FALSE) -> Diabetes | L11: =VLOOKUP(Healthcare!$A11,'Hospitalisation Details_A_sheet'!$A$1:$K$2344,COLUMN('Hospitalisation Details_A_sheet'!F10),FALSE) -> 48885.14 | M11: =VLOOKUP(Healthcare!$A11,'Hospitalisation Details_A_sheet'!$A$1:$K$2344,COLUMN('Hospitalisation Details_A_sheet'!G10),FALSE) -> tier - 1 | N11: =VLOOKUP(Healthcare!$A11,'Hospitalisation Details_A_sheet'!$A$1:$K$2344,COLUMN('Hospitalisation Details_A_sheet'!H10),FALSE) -> tier - 2 | O11: =VLOOKUP(Healthcare!$A11,'Hospitalisation Details_A_sheet'!$A$1:$K$2344,COLUMN('Hospitalisation Details_A_sheet'!I10),FALSE) -> R1013 | P11: =VLOOKUP(Healthcare!$A11,'Hospitalisation Details_A_sheet'!$A$1:$K$2344,COLUMN('Hospitalisation Details_A_sheet'!J10),FALSE) -> 29-Dec-1978 | Q11: =VLOOKUP(Healthcare!$A11,'Hospitalisation Details_A_sheet'!$A$1:$K$2344,COLUMN('Hospitalisation Details_A_sheet'!K10),FALSE) -> 44
A12: Id11 | B12: =VLOOKUP('Customer Names_A_sheet'!$A12,'Customer Names_A_sheet'!$A$1:$E$2336,4,FALSE) -> Ms. Paola Andrea | C12: =VLOOKUP($A12, 'Medical Examinations_A_sheet'!$A$1:$J$2336, COLUMN('Medical Examinations_A_sheet'!B12), FALSE) -> 37.7 | D12: =VLOOKUP($A12, 'Medical Examinations_A_sheet'!$A$1:$J$2336, COLUMN('Medical Examinations_A_sheet'!C12), FALSE) -> 5.96 | E12: =VLOOKUP($A12, 'Medical Examinations_A_sheet'!$A$1:$J$2336, COLUMN('Medical Examinations_A_sheet'!D12), FALSE) -> Yes | F12: =VLOOKUP($A12, 'Medical Examinations_A_sheet'!$A$1:$J$2336, COLUMN('Medical Examinations_A_sheet'!E12), FALSE) -> No | G12: =VLOOKUP($A12, 'Medical Examinations_A_sheet'!$A$1:$J$2336, COLUMN('Medical Examinations_A_sheet'!F12), FALSE) -> No | H12: =VLOOKUP($A12, 'Medical Examinations_A_sheet'!$A$1:$J$2336, COLUMN('Medical Examinations_A_sheet'!G12), FALSE) -> 2 | I12: =VLOOKUP($A12, 'Medical Examinations_A_sheet'!$A$1:$J$2336, COLUMN('Medical Examinations_A_sheet'!H12), FALSE) -> Yes | J12: =VLOOKUP($A12, 'Medical Examinations_A_sheet'!$A$1:$J$2336, COLUMN('Medical Examinations_A_sheet'!I12), FALSE) -> Obesity | K12: =VLOOKUP($A12, 'Medical Examinations_A_sheet'!$A$1:$J$2336, COLUMN('Medical Examinations_A_sheet'!J12), FALSE) -> Prediabetes | L12: =VLOOKUP(Healthcare!$A12,'Hospitalisation Details_A_sheet'!$A$1:$K$2344,COLUMN('Hospitalisation Details_A_sheet'!F11),FALSE) -> 48824.45 | M12: =VLOOKUP(Healthcare!$A12,'Hospitalisation Details_A_sheet'!$A$1:$K$2344,COLUMN('Hospitalisation Details_A_sheet'!G11),FALSE) -> tier - 2 | N12: =VLOOKUP(Healthcare!$A12,'Hospitalisation Details_A_sheet'!$A$1:$K$2344,COLUMN('Hospitalisation Details_A_sheet'!H11),FALSE) -> tier - 1 | O12: =VLOOKUP(Healthcare!$A12,'Hospitalisation Details_A_sheet'!$A$1:$K$2344,COLUMN('Hospitalisation Details_A_sheet'!I11),FALSE) -> R1011 | P12: =VLOOKUP(Healthcare!$A12,'Hospitalisation Details_A_sheet'!$A$1:$K$2344,COLUMN('Hospitalisation Details_A_sheet'!J11),FALSE) -> 22-Jul-1959 | Q12: =VLOOKUP(Healthcare!$A12,'Hospitalisation Details_A_sheet'!$A$1:$K$2344,COLUMN('Hospitalisation Details_A_sheet'!K11),FALSE) -> 63
A13: Id12 | B13: =VLOOKUP('Customer Names_A_sheet'!$A13,'Customer Names_A_sheet'!$A$1:$E$2336,4,FALSE) -> David | C13: =VLOOKUP($A13, 'Medical Examinations_A_sheet'!$A$1:$J$2336, COLUMN('Medical Examinations_A_sheet'!B13), FALSE) -> 42.13 | D13: =VLOOKUP($A13, 'Medical Examinations_A_sheet'!$A$1:$J$2336, COLUMN('Medical Examinations_A_sheet'!C13), FALSE) -> 11.9 | E13: =VLOOKUP($A13, 'Medical Examinations_A_sheet'!$A$1:$J$2336, COLUMN('Medical Examinations_A_sheet'!D13), FALSE) -> No | F13: =VLOOKUP($A13, 'Medical Examinations_A_sheet'!$A$1:$J$2336, COLUMN('Medical Examinations_A_sheet'!E13), FALSE) -> No | G13: =VLOOKUP($A13, 'Medical Examinations_A_sheet'!$A$1:$J$2336, COLUMN('Medical Examinations_A_sheet'!F13), FALSE) -> No | H13: =VLOOKUP($A13, 'Medical Examinations_A_sheet'!$A$1:$J$2336, COLUMN('Medical Examinations_A_sheet'!G13), FALSE) -> 0 | I13: =VLOOKUP($A13, 'Medical Examinations_A_sheet'!$A$1:$J$2336, COLUMN('Medical Examinations_A_sheet'!H13), FALSE) -> Yes | J13: =VLOOKUP($A13, 'Medical Examinations_A_sheet'!$A$1:$J$2336, COLUMN('Medical Examinations_A_sheet'!I13), FALSE) -> Obesity | K13: =VLOOKUP($A13, 'Medical Examinations_A_sheet'!$A$1:$J$2336, COLUMN('Medical Examinations_A_sheet'!J13), FALSE) -> Diabetes | L13: =VLOOKUP(Healthcare!$A13,'Hospitalisation Details_A_sheet'!$A$1:$K$2344,COLUMN('Hospitalisation Details_A_sheet'!F12),FALSE) -> 48675.52 | M13: =VLOOKUP(Healthcare!$A13,'Hospitalisation Details_A_sheet'!$A$1:$K$2344,COLUMN('Hospitalisation Details_A_sheet'!G12),FALSE) -> tier - 1 | N13: =VLOOKUP(Healthcare!$A13,'Hospitalisation Details_A_sheet'!$A$1:$K$2344,COLUMN('Hospitalisation Details_A_sheet'!H12),FALSE) -> tier - 2 | O13: =VLOOKUP(Healthcare!$A13,'Hospitalisation Details_A_sheet'!$A$1:$K$2344,COLUMN('Hospitalisation Details_A_sheet'!I12),FALSE) -> R1013 | P13: =VLOOKUP(Healthcare!$A13,'Hospitalisation Details_A_sheet'!$A$1:$K$2344,COLUMN('Hospitalisation Details_A_sheet'!J12),FALSE) -> 27-Oct-1965 | Q13: =VLOOKUP(Healthcare!$A13,'Hospitalisation Details_A_sheet'!$A$1:$K$2344,COLUMN('Hospitalisation Details_A_sheet'!K12),FALSE) -> 57
... A2336: Id2335 | B2336: =VLOOKUP('Customer Names_A_sheet'!$A2336,'Customer Names_A_sheet'!$A$1:$E$2336,4,FALSE) -> Aaron K | C2336: =VLOOKUP($A2336, 'Medical Examinations_A_sheet'!$A$1:$J$2336, COLUMN('Medical Examinations_A_sheet'!B2336), FALSE) -> 17.58 | D2336: =VLOOKUP($A2336, 'Medical Examinations_A_sheet'!$A$1:$J$2336, COLUMN('Medical Examinations_A_sheet'!C2336), FALSE) -> 4.51 | E2336: =VLOOKUP($A2336, 'Medical Examinations_A_sheet'!$A$1:$J$2336, COLUMN('Medical Examinations_A_sheet'!D2336), FALSE) -> No | F2336: =VLOOKUP($A2336, 'Medical Examinations_A_sheet'!$A$1:$J$2336, COLUMN('Medical Examinations_A_sheet'!E2336), FALSE) -> No | G2336: =VLOOKUP($A2336, 'Medical Examinations_A_sheet'!$A$1:$J$2336, COLUMN('Medical Examinations_A_sheet'!F2336), FALSE) -> No | H2336: =VLOOKUP($A2336, 'Medical Examinations_A_sheet'!$A$1:$J$2336, COLUMN('Medical Examinations_A_sheet'!G2336), FALSE) -> 1 | I2336: =VLOOKUP($A2336, 'Medical Examinations_A_sheet'!$A$1:$J$2336, COLUMN('Medical Examinations_A_sheet'!H2336), FALSE) -> No | J2336: =VLOOKUP($A2336, 'Medical Examinations_A_sheet'!$A$1:$J$2336, COLUMN('Medical Examinations_A_sheet'!I2336), FALSE) -> Underweight | K2336: =VLOOKUP($A2336, 'Medical Examinations_A_sheet'!$A$1:$J$2336, COLUMN('Medical Examinations_A_sheet'!J2336), FALSE) -> Normal | L2336: =VLOOKUP(Healthcare!$A2336,'Hospitalisation Details_A_sheet'!$A$1:$K$2344,COLUMN('Hospitalisation Details_A_sheet'!F2335),FALSE) -> 563.84 | M2336: =VLOOKUP(Healthcare!$A2336,'Hospitalisation Details_A_sheet'!$A$1:$K$2344,COLUMN('Hospitalisation Details_A_sheet'!G2335),FALSE) -> tier - 2 | N2336: =VLOOKUP(Healthcare!$A2336,'Hospitalisation Details_A_sheet'!$A$1:$K$2344,COLUMN('Hospitalisation Details_A_sheet'!H2335),FALSE) -> tier - 3 | O2336: =VLOOKUP(Healthcare!$A2336,'Hospitalisation Details_A_sheet'!$A$1:$K$2344,COLUMN('Hospitalisation Details_A_sheet'!I2335),FALSE) -> R1013 | P2336: =VLOOKUP(Healthcare!$A2336,'Hospitalisation Details_A_sheet'!$A$1:$K$2344,COLUMN('Hospitalisation Details_A_sheet'!J2335),FALSE) -> 9-Jul-1992 | Q2336: =VLOOKUP(Healthcare!$A2336,'Hospitalisation Details_A_sheet'!$A$1:$K$2344,COLUMN('Hospitalisation Details_A_sheet'!K2335),FALSE) -> 30

Sheet Pie_Donut
A1: smoker | B1: Cancer history | C1: Count of Cancer history
A2: No | B2: No | C2: 1540 | H2: Transplants | I2: Sum of NumberOfMajorSurgeries | J2: Average of HBA1C | K2: Count of Customer ID
B3: Yes | C3: 307 | H3: No | I3: 1417 | J3: 6.6704427 | K3: 2191
A4: No Total | C4: 1847 | H4: yes | I4: 162 | J4: 5.1876389 | K4: 144
A5: Yes | B5: No | C5: 404 | H5: Grand Total | I5: 1579 | J5: 6.5789979 | K5: 2335
B6: Yes | C6: 84
A7: Yes Total | C7: 488
A8: Grand Total | C8: 2335

Sheet Column_Bar Chart
A1: Sum of charges | B1: Column Labels | H1: Average of charges | I1: Column Labels
A2: Row Labels | B2: Diabetes | C2: Normal | D2: Prediabetes | E2: Grand Total | H2: Row Labels | I2: tier - 1 | J2: tier - 2 | K2: tier - 3 | L2: Grand Total
A3: Normal Weight | B3: 1730218.2 | C3: 1714717.2 | D3: 860354.71 | E3: 4305290.1 | H3: R1011 | I3: 33081.374 | J3: 18997.281 | K3: 9250.3618 | L3: 19466.246
A4: Obesity | B4: 8184059.1 | C4: 8520712.9 | D4: 3638874.8 | E4: 20343647 | H4: R1012 | I4: 26111.458 | J4: 10334.279 | K4: 10179.942 | L4: 12016.474
A5: Overweight | B5: 2240235.2 | C5: 2437209 | D5: 1051697.5 | E5: 5729141.8 | H5: R1013 | I5: 31328.102 | J5: 8439.2844 | K5: 6890.7568 | L5: 10514.94
A6: Underweight | B6: 483792.72 | C6: 566702.46 | D6: 163784.7 | E6: 1214279.9 | H6: R1014 | I6: 13891.86 | J6: 2395.17 | K6: 16950.485 | L6: 13478.057
A7: Grand Total | B7: 12638305 | C7: 13239342 | D7: 5714711.8 | E7: 31592359 | H7: R1015 | I7: 21523.52 | J7: 15675.543 | K7: 7570.755 | L7: 13948.61
H8: R1016 | I8: 39868.616 | J8: 16075.963 | K8: 8133.0084 | L8: 13589.263
H9: R1017 | I9: 34070.596 | J9: 11365.622 | K9: 8667.3662 | L9: 14806.108
H10: R1018 | I10: 33475.82 | J10: 10139.553 | K10: 12570.97 | L10: 13272.787
H11: R1019 | I11: 27621.61 | J11: 8116.72 | K11: 12706.976 | L11: 13633.143
H12: R1020 | J12: 6760.5433 | K12: 11716.453 | L12: 9238.4983
H13: R1021 | J13: 7668.1787 | K13: 11518.786 | L13: 8933.3781
H14: R1022 | J14: 10102.027 | K14: 11637.812 | L14: 10650.521
H15: R1023 | I15: 18261.757 | J15: 13457.095 | K15: 12785.637 | L15: 13786.149
H16: R1024 | I16: 32732.187 | J16: 10174.346 | K16: 13360.979 | L16: 12865.149
H17: R1025 | J17: 6886.0368 | K17: 10510.314 | L17: 8788.7823
H18: R1026 | I18: 18709.798 | J18: 11919.608 | K18: 12296.78 | L18: 12489.921
H19: Unknown | I19: 20996.53 | L19: 20996.53
H20: Grand Total | I20: 30129.199 | J20: 11865.269 | K20: 9462.2693 | L20: 13529.918

Sheet line_scatter
A1: Row Labels | B1: Average of BMI | C1: Average of HBA1C | N1: Age | O1: charges
A2: 18 | B2: 31.260372 | C2: 5.1409574 | N2: 54 | O2: 63770.43
A3: 19 | B3: 29.654186 | C3: 5.1781395 | N3: 46 | O3: 62592.87
A4: 20 | B4: 28.018276 | C4: 9.3244828 | N4: 52 | O4: 60021.4
A5: 21 | B5: 29.273721 | C5: 5.1174419 | N5: 32 | O5: 58571.07
A6: 22 | B6: 32.581827 | C6: 5.2767308 | N6: 33 | O6: 55135.4
A7: 23 | B7: 30.8293 | C7: 5.1892 | N7: 60 | O7: 52590.83
A8: 24 | B8: 29.0175 | C8: 5.1626087 | N8: 28 | O8: 51194.56
A9: 25 | B9: 30.344211 | C9: 5.2589474 | N9: 64 | O9: 49577.66
A10: 26 | B10: 30.441364 | C10: 5.1029545 | N10: 59 | O10: 48970.25
A11: 27 | B11: 30.316275 | C11: 4.9407843 | N11: 44 | O11: 48885.14
A12: 28 | B12: 31.029286 | C12: 5.2207143 | N12: 63 | O12: 48824.45
A13: 29 | B13: 30.763302 | C13: 5.2043396 | N13: 57 | O13: 48675.52
... A49: 65 | B49: 26.885 | C49: 9.86 | N49: 42 | O49: 43896.38
A50: Grand Total | B50: 30.972649 | C50: 6.5789979 | N50: 56 | O50: 43817.45
N51: 56 | O51: 43813.87
N52: 36 | O52: 43753.34
N53: 57 | O53: 43578.94
N54: 53 | O54: 43254.42
N55: 57 | O55: 43073.76
N56: 44 | O56: 42983.46
N57: 47 | O57: 42969.85
N58: 50 | O58: 42856.84
N59: 57 | O59: 42764.12
N60: 45 | O60: 42760.5
N61: 51 | O61: 42644.2
N62: 43 | O62: 42560.43
... N2336: 30 | O2336: 563.84

Sheet Interactive_dashboard
D1: HEALTHCARE OUTCOMES & MEDICAL CHARGES ANALYSIS
E8: Smoker | F8: Count of Cancer history | H8: Transplants | I8: Sum of NumberOfMajorSurgeries | J8: Average of HBA1C | K8: Count of Customer ID | M8: Sum of charges | N8: Column Labels
E9: No | F9: 1847 | H9: No | I9: 1417 | J9: 6.6704427 | K9: 2191 | M9: Row Labels | N9: Diabetes | O9: Normal | P9: Prediabetes | Q9: Grand Total
E10: No | F10: 1540 | H10: yes | I10: 162 | J10: 5.1876389 | K10: 144 | M10: Normal Weight | N10: 1730218.2 | O10: 1714717.2 | P10: 860354.71 | Q10: 4305290.1
E11: Yes | F11: 307 | H11: Grand Total | I11: 1579 | J11: 6.5789979 | K11: 2335 | M11: Obesity | N11: 8184059.1 | O11: 8520712.9 | P11: 3638874.8 | Q11: 20343647
E12: Yes | F12: 488 | M12: Overweight | N12: 2240235.2 | O12: 2437209 | P12: 1051697.5 | Q12: 5729141.8
E13: No | F13: 404 | M13: Underweight | N13: 483792.72 | O13: 566702.46 | P13: 163784.7 | Q13: 1214279.9
E14: Yes | F14: 84 | M14: Grand Total | N14: 12638305 | O14: 13239342 | P14: 5714711.8 | Q14: 31592359
E15: Grand Total | F15: 2335
E43: Average of charges | F43: Column Labels
E44: Row Labels | F44: tier - 1 | G44: tier - 2 | H44: tier - 3 | I44: Grand Total
E45: R1011 | F45: 33081.374 | G45: 18997.281 | H45: 9250.3618 | I45: 19466.246
E46: R1012 | F46: 26111.458 | G46: 10334.279 | H46: 10179.942 | I46: 12016.474
E47: R1013 | F47: 31328.102 | G47: 8439.2844 | H47: 6890.7568 | I47: 10514.94
E48: R1014 | F48: 13891.86 | G48: 2395.17 | H48: 16950.485 | I48: 13478.057
E49: R1015 | F49: 21523.52 | G49: 15675.543 | H49: 7570.755 | I49: 13948.61
E50: R1016 | F50: 39868.616 | G50: 16075.963 | H50: 8133.0084 | I50: 13589.263
E51: R1017 | F51: 34070.596 | G51: 11365.622 | H51: 8667.3662 | I51: 14806.108
E52: R1018 | F52: 33475.82 | G52: 10139.553 | H52: 12570.97 | I52: 13272.787
E53: R1019 | F53: 27621.61 | G53: 8116.72 | H53: 12706.976 | I53: 13633.143
E54: R1020 | G54: 6760.5433 | H54: 11716.453 | I54: 9238.4983
E55: R1021 | G55: 7668.1787 | H55: 11518.786 | I55: 8933.3781
E56: R1022 | G56: 10102.027 | H56: 11637.812 | I56: 10650.521
E57: R1023 | F57: 18261.757 | G57: 13457.095 | H57: 12785.637 | I57: 13786.149
E58: R1024 | F58: 32732.187 | G58: 10174.346 | H58: 13360.979 | I58: 12865.149
E59: R1025 | G59: 6886.0368 | H59: 10510.314 | I59: 8788.7823
E60: R1026 | F60: 18709.798 | G60: 11919.608 | H60: 12296.78 | I60: 12489.921
E61: Unknown | F61: 20996.53 | I61: 20996.53
E62: Grand Total | F62: 30129.199 | G62: 11865.269 | H62: 9462.2693 | I62: 13529.918
E67: Average of BMI | F67: Average of HBA1C
E68: 31.260372 | F68: 5.1409574
E69: 29.654186 | F69: 5.1781395
E70: 28.018276 | F70: 9.3244828
E71: 29.273721 | F71: 5.1174419
E72: 32.581827 | F72: 5.2767308
E73: 30.8293 | F73: 5.1892
E74: 29.0175 | F74: 5.1626087
E75: 30.344211 | F75: 5.2589474
E76: 30.441364 | F76: 5.1029545
E77: 30.316275 | F77: 4.9407843
...
